Workbook
Name BBDD: [1]BBDD!$A$2:$W$109
Name BBDD: #REF!
Name EAN: [1]EAN!$A$3:$C$8547
Name EAN: EAN!$A$3:$C$8547
Name ENVIO: #REF!
Name ENVIO: #REF!
Name PVP: #REF!
Name PVP: #REF!
Name TP: '[1]T.P.'!$A$2:$B$3
Name TP: 'T.P.'!$A$2:$B$3

Sheet RESUMEN PEDIDO
B1: KIN COSMETICS, S.A.U. | J1: EDICIÓN FEBRERO 2026
B2: HOJA DE PEDIDO DISTRIBUIDOR
H3: Nº PEDIDO:
H4: Nº FACTURA:
H5: FECHA FACTURA:
B6: DATOS
B8: FECHA PEDIDO
B9: =NOW() -> 46079.371
B11: DATOS CLIENTE
B12: CÓD. CLIENTE | D12: NOMBRE | E12: =VLOOKUP(C12,'BBDD ACTUALITZADA'!A2:O103,2,FALSE) -> #N/A
B13: DIRECCIÓN | C13: =VLOOKUP(C12,'BBDD ACTUALITZADA'!A2:O103,4,FALSE) -> #N/A
B14: POBLACIÓN | C14: =VLOOKUP(C12,'BBDD ACTUALITZADA'!A2:O103,6,FALSE) -> #N/A | H14: C.P. | J14: =VLOOKUP(C12,'BBDD ACTUALITZADA'!A2:O103,5,FALSE) -> #N/A
B15: PROVÍNCIA | C15: =VLOOKUP(C12,'BBDD ACTUALITZADA'!A2:O103,7,FALSE) -> #N/A | H15: TELÉFONO | J15: =VLOOKUP(C12,'BBDD ACTUALITZADA'!A2:O103,8,FALSE) -> #N/A
B16: PAÍS | C16: =VLOOKUP(C12,'BBDD ACTUALITZADA'!A2:P103,16) -> #N/A
B18: DATOS ENVÍO
B19: DIRECCIÓN | C19: =VLOOKUP(C12,'BBDD ACTUALITZADA'!A2:P103,4,FALSE) -> #N/A
B20: DIRECCIÓN 2 | C20: =VLOOKUP(C12,BBDD,21,0) -> #REF!
B21: POBLACIÓN | C21: =VLOOKUP(C12,'BBDD ACTUALITZADA'!A9:O110,6,FALSE) -> #N/A | H21: C.P. | J21: =VLOOKUP(C12,'BBDD ACTUALITZADA'!A9:O110,5,FALSE) -> #N/A
B22: PROVÍNCIA | C22: =VLOOKUP(C12,'BBDD ACTUALITZADA'!A9:O110,7,FALSE) -> #N/A | H22: TELÉFONO | J22: =J15 -> #N/A
B23: PAÍS | C23: =C16 -> #N/A
B25: ASESOR COMERCIAL
B26: CÓDIGO | C26: =VLOOKUP(C12,'BBDD ACTUALITZADA'!A2:P103,10,FALSE) -> #N/A | D26: NOMBRE | E26: =VLOOKUP(C12,'BBDD ACTUALITZADA'!A2:Q103,17,FALSE) -> #N/A
B28: DESCUENTO CLIENTE
B29: DESCUENTO 1
B30: DESCUENTO 2
B31: DTO. MAT. MKT | C31: 0.7
B33: RESUMEN PEDIDO
B35: SUBTOTAL PRODUCTO TÉCNICO | J35: ='PRODUCTO TÉCNICO'!M7 -> 0
B36: SUBTOTAL PRODUCTO REVENTA | J36: ='PRODUCTO REVENTA'!M7 -> 0
B37: SUBTOTAL PRODUCTOS | J37: =J35+J36 -> 0
B38: SUBTOTAL PROMOCIONES (no acumula para Material Marketing)
C41: CRÉDITO EN MATERIAL DE MARKETING | G41: 0.03 | H41: =(J37-J38)*G41 -> 0
C43: CRÉDITO EN MATERIAL DE MARKETING GASTADO | H43: ='MATERIAL MARKETING'!H7+'MATERIAL MKT OUTLET'!G7 -> 0
C45: *TOTAL MATERIAL DE MARKETING | H45: =H41-H43 -> 0 | J45: =IF(H45<0,"A PAGAR",IF(H45>0,"A COMPENSAR","COMPENSADO")) -> COMPENSADO
B47: *El importe pendiente a compensar, no es acumulativo y tampoco se abona.
B49: RESUMEN PEDIDO OUTLET
B51: SUBTOTAL OUTLET (acumula para Material Marketing Outlet) | J51: ='PRODUCTO OUTLET'!J7 -> 0
C54: CRÉDITO EN MATERIAL DE MARKETING | H54: =J51*G54 -> 0
C56: CRÉDITO EN MATERIAL DE MARKETING GASTADO | H56: ='MATERIAL MKT OUTLET'!G7 -> 0
C58: *TOTAL MATERIAL DE MARKETING | H58: =H54-H56 -> 0 | J58: =IF(H58<0,"A PAGAR",IF(H58>0,"A COMPENSAR","COMPENSADO")) -> COMPENSADO
...

Sheet PRODUCTO TÉCNICO
B1: KIN COSMETICS, S.A.U.
B2: HOJA DE PEDIDO DISTRIBUIDOR
B6: PRODUCTO TÉCNICO
B7: SUBTOTAL PRODUCTO TÉCNICO | D7: =D9+D133+D223+D231+D240+D252+D260+D267+D271+D277+D279+D302+D203+D249 -> 0 | J7: =SUBTOTAL(9,J10:J132,J134:J202,J204:J222,J224:J230,J232:J239,J241:J248,J250:J251,J268:J270,J253:J259,J272:J276,J261:J266,J278:J278,J280:J301,J303:J309) -> 0 | M7: =SUBTOTAL(9,M9:M309) -> 0
B8: Ref. | C8: Descripción | D8: Unidades | E8: Precio Tarifa | F8: PVP | G8: Código EAN | H8: Formato | I8: Packing | J8: Cajas | K8: Dto. 1% | L8: Dto. 2% | M8: Subtotal
B9: KINCREM COLOR / COLORACIÓN | D9: =SUM(D10:D132) -> 0 | I9: 12 | J9: =D9/I9 -> 0
B10: 502001 | C10: KINCREM COLOR 1.0 | E10: 36.9 | F10: 40.6 | G10: =VLOOKUP(B10,EAN,3,0) -> 8435057015233 | H10: 3 x 100 ml | I10: 12 | J10: =D10/I10 -> 0 | K10: ='RESUMEN PEDIDO'!$C$29 -> 0 | L10: ='RESUMEN PEDIDO'!$C$30 -> 0 | M10: =(D10*(E10-(E10*K10)))-(D10*(E10-(E10*K10)))*L10 -> 0
B11: 502002 | C11: KINCREM COLOR 2.0 | E11: 36.9 | F11: 40.6 | G11: =VLOOKUP(B11,EAN,3,0) -> 8435057015240 | H11: 3 x 100 ml | I11: 12 | J11: =D11/I11 -> 0 | K11: ='RESUMEN PEDIDO'!$C$29 -> 0 | L11: ='RESUMEN PEDIDO'!$C$30 -> 0 | M11: =(D11*(E11-(E11*K11)))-(D11*(E11-(E11*K11)))*L11 -> 0
B12: 502003 | C12: KINCREM COLOR 3.0 | E12: 36.9 | F12: 40.6 | G12: =VLOOKUP(B12,EAN,3,0) -> 8435057015257 | H12: 3 x 100 ml | I12: 12 | J12: =D12/I12 -> 0 | K12: ='RESUMEN PEDIDO'!$C$29 -> 0 | L12: ='RESUMEN PEDIDO'!$C$30 -> 0 | M12: =(D12*(E12-(E12*K12)))-(D12*(E12-(E12*K12)))*L12 -> 0
B13: 502004 | C13: KINCREM COLOR 4.0 | E13: 36.9 | F13: 40.6 | G13: =VLOOKUP(B13,EAN,3,0) -> 8435057015264 | H13: 3 x 100 ml | I13: 12 | J13: =D13/I13 -> 0 | K13: ='RESUMEN PEDIDO'!$C$29 -> 0 | L13: ='RESUMEN PEDIDO'!$C$30 -> 0 | M13: =(D13*(E13-(E13*K13)))-(D13*(E13-(E13*K13)))*L13 -> 0
B14: 502005 | C14: KINCREM COLOR 5.0 | E14: 36.9 | F14: 40.6 | G14: =VLOOKUP(B14,EAN,3,0) -> 8435057015271 | H14: 3 x 100 ml | I14: 12 | J14: =D14/I14 -> 0 | K14: ='RESUMEN PEDIDO'!$C$29 -> 0 | L14: ='RESUMEN PEDIDO'!$C$30 -> 0 | M14: =(D14*(E14-(E14*K14)))-(D14*(E14-(E14*K14)))*L14 -> 0
B15: 502006 | C15: KINCREM COLOR 6.0 | E15: 36.9 | F15: 40.6 | G15: =VLOOKUP(B15,EAN,3,0) -> 8435057015288 | H15: 3 x 100 ml | I15: 12 | J15: =D15/I15 -> 0 | K15: ='RESUMEN PEDIDO'!$C$29 -> 0 | L15: ='RESUMEN PEDIDO'!$C$30 -> 0 | M15: =(D15*(E15-(E15*K15)))-(D15*(E15-(E15*K15)))*L15 -> 0
B16: 502007 | C16: KINCREM COLOR 7.0 | E16: 36.9 | F16: 40.6 | G16: =VLOOKUP(B16,EAN,3,0) -> 8435057015295 | H16: 3 x 100 ml | I16: 12 | J16: =D16/I16 -> 0 | K16: ='RESUMEN PEDIDO'!$C$29 -> 0 | L16: ='RESUMEN PEDIDO'!$C$30 -> 0 | M16: =(D16*(E16-(E16*K16)))-(D16*(E16-(E16*K16)))*L16 -> 0
B17: 502008 | C17: KINCREM COLOR 8.0 | E17: 36.9 | F17: 40.6 | G17: =VLOOKUP(B17,EAN,3,0) -> 8435057015301 | H17: 3 x 100 ml | I17: 12 | J17: =D17/I17 -> 0 | K17: ='RESUMEN PEDIDO'!$C$29 -> 0 | L17: ='RESUMEN PEDIDO'!$C$30 -> 0 | M17: =(D17*(E17-(E17*K17)))-(D17*(E17-(E17*K17)))*L17 -> 0
B18: 502009 | C18: KINCREM COLOR 9.0 | E18: 36.9 | F18: 40.6 | G18: =VLOOKUP(B18,EAN,3,0) -> 8435057015318 | H18: 3 x 100 ml | I18: 12 | J18: =D18/I18 -> 0 | K18: ='RESUMEN PEDIDO'!$C$29 -> 0 | L18: ='RESUMEN PEDIDO'!$C$30 -> 0 | M18: =(D18*(E18-(E18*K18)))-(D18*(E18-(E18*K18)))*L18 -> 0
B19: 502010 | C19: KINCREM COLOR 10.0 | E19: 36.9 | F19: 40.6 | G19: =VLOOKUP(B19,EAN,3,0) -> 8435057015325 | H19: 3 x 100 ml | I19: 12 | J19: =D19/I19 -> 0 | K19: ='RESUMEN PEDIDO'!$C$29 -> 0 | L19: ='RESUMEN PEDIDO'!$C$30 -> 0 | M19: =(D19*(E19-(E19*K19)))-(D19*(E19-(E19*K19)))*L19 -> 0
B20: 502011 | C20: KINCREM COLOR 3.00 | E20: 36.9 | F20: 40.6 | G20: =VLOOKUP(B20,EAN,3,0) -> 8435057015332 | H20: 3 x 100 ml | I20: 12 | J20: =D20/I20 -> 0 | K20: ='RESUMEN PEDIDO'!$C$29 -> 0 | L20: ='RESUMEN PEDIDO'!$C$30 -> 0 | M20: =(D20*(E20-(E20*K20)))-(D20*(E20-(E20*K20)))*L20 -> 0
B21: 502012 | C21: KINCREM COLOR 4.00 | E21: 36.9 | F21: 40.6 | G21: =VLOOKUP(B21,EAN,3,0) -> 8435057015349 | H21: 3 x 100 ml | I21: 12 | J21: =D21/I21 -> 0 | K21: ='RESUMEN PEDIDO'!$C$29 -> 0 | L21: ='RESUMEN PEDIDO'!$C$30 -> 0 | M21: =(D21*(E21-(E21*K21)))-(D21*(E21-(E21*K21)))*L21 -> 0
... B129: 502120 | C129: KINCREM COLOR M/99 | E129: 36.9 | F129: 40.6 | G129: =VLOOKUP(B129,EAN,3,0) -> 8435057016421 | H129: 3 x 100 ml | I129: 12 | J129: =D129/I129 -> 0 | K129: ='RESUMEN PEDIDO'!$C$29 -> 0 | L129: ='RESUMEN PEDIDO'!$C$30 -> 0 | M129: =(D129*(E129-(E129*K129)))-(D129*(E129-(E129*K129)))*L129 -> 0
B130: 502154 | C130: KINCREM COLOR 5.521 - MOCHA MOUSSE COLLECTION | E130: 36.9 | F130: 40.6 | G130: 8435057020350 | H130: 3 x 100 ml | I130: 12 | J130: =D130/I130 -> 0 | K130: ='RESUMEN PEDIDO'!$C$29 -> 0 | L130: ='RESUMEN PEDIDO'!$C$30 -> 0 | M130: =(D130*(E130-(E130*K130)))-(D130*(E130-(E130*K130)))*L130 -> 0
B131: 502155 | C131: KINCREM COLOR 7.521 - MOCHA MOUSSE COLLECTION | E131: 36.9 | F131: 40.6 | G131: 8435057020367 | H131: 3 x 100 ml | I131: 12 | J131: =D131/I131 -> 0 | K131: ='RESUMEN PEDIDO'!$C$29 -> 0 | L131: ='RESUMEN PEDIDO'!$C$30 -> 0 | M131: =(D131*(E131-(E131*K131)))-(D131*(E131-(E131*K131)))*L131 -> 0
B132: 502156 | C132: KINCREM COLOR 8.521 - MOCHA MOUSSE COLLECTION | E132: 36.9 | F132: 40.6 | G132: 8435057020344 | H132: 3 x 100 ml | I132: 12 | J132: =D132/I132 -> 0 | K132: ='RESUMEN PEDIDO'!$C$29 -> 0 | L132: ='RESUMEN PEDIDO'!$C$30 -> 0 | M132: =(D132*(E132-(E132*K132)))-(D132*(E132-(E132*K132)))*L132 -> 0
B133: KINESSENCES COLOR / COLORACIÓN | D133: =SUM(D134:D202) -> 0 | I133: 12 | J133: =D133/I133 -> 0
B134: 513101 | C134: KINESSENCES COLOR 1.0 | E134: 36.9 | F134: 40.6 | G134: =VLOOKUP(B134,EAN,3,0) -> 8435057017237 | H134: 3 x 100 ml | I134: 12 | J134: =D134/I134 -> 0 | K134: ='RESUMEN PEDIDO'!$C$29 -> 0 | L134: ='RESUMEN PEDIDO'!$C$30 -> 0 | M134: =(D134*(E134-(E134*K134)))-(D134*(E134-(E134*K134)))*L134 -> 0
B135: 513102 | C135: KINESSENCES COLOR 3.0 | E135: 36.9 | F135: 40.6 | G135: =VLOOKUP(B135,EAN,3,0) -> 8435057017251 | H135: 3 x 100 ml | I135: 12 | J135: =D135/I135 -> 0 | K135: ='RESUMEN PEDIDO'!$C$29 -> 0 | L135: ='RESUMEN PEDIDO'!$C$30 -> 0 | M135: =(D135*(E135-(E135*K135)))-(D135*(E135-(E135*K135)))*L135 -> 0
B136: 513103 | C136: KINESSENCES COLOR 4.0 | E136: 36.9 | F136: 40.6 | G136: =VLOOKUP(B136,EAN,3,0) -> 8435057017268 | H136: 3 x 100 ml | I136: 12 | J136: =D136/I136 -> 0 | K136: ='RESUMEN PEDIDO'!$C$29 -> 0 | L136: ='RESUMEN PEDIDO'!$C$30 -> 0 | M136: =(D136*(E136-(E136*K136)))-(D136*(E136-(E136*K136)))*L136 -> 0
B137: 513104 | C137: KINESSENCES COLOR 5.0 | E137: 36.9 | F137: 40.6 | G137: =VLOOKUP(B137,EAN,3,0) -> 8435057017275 | H137: 3 x 100 ml | I137: 12 | J137: =D137/I137 -> 0 | K137: ='RESUMEN PEDIDO'!$C$29 -> 0 | L137: ='RESUMEN PEDIDO'!$C$30 -> 0 | M137: =(D137*(E137-(E137*K137)))-(D137*(E137-(E137*K137)))*L137 -> 0
B138: 513105 | C138: KINESSENCES COLOR 6.0 | E138: 36.9 | F138: 40.6 | G138: =VLOOKUP(B138,EAN,3,0) -> 8435057017282 | H138: 3 x 100 ml | I138: 12 | J138: =D138/I138 -> 0 | K138: ='RESUMEN PEDIDO'!$C$29 -> 0 | L138: ='RESUMEN PEDIDO'!$C$30 -> 0 | M138: =(D138*(E138-(E138*K138)))-(D138*(E138-(E138*K138)))*L138 -> 0
B139: 513106 | C139: KINESSENCES COLOR 7.0 | E139: 36.9 | F139: 40.6 | G139: =VLOOKUP(B139,EAN,3,0) -> 8435057017299 | H139: 3 x 100 ml | I139: 12 | J139: =D139/I139 -> 0 | K139: ='RESUMEN PEDIDO'!$C$29 -> 0 | L139: ='RESUMEN PEDIDO'!$C$30 -> 0 | M139: =(D139*(E139-(E139*K139)))-(D139*(E139-(E139*K139)))*L139 -> 0
B140: 513107 | C140: KINESSENCES COLOR 8.0 | E140: 36.9 | F140: 40.6 | G140: =VLOOKUP(B140,EAN,3,0) -> 8435057017305 | H140: 3 x 100 ml | I140: 12 | J140: =D140/I140 -> 0 | K140: ='RESUMEN PEDIDO'!$C$29 -> 0 | L140: ='RESUMEN PEDIDO'!$C$30 -> 0 | M140: =(D140*(E140-(E140*K140)))-(D140*(E140-(E140*K140)))*L140 -> 0
B141: 513108 | C141: KINESSENCES COLOR 9.0 | E141: 36.9 | F141: 40.6 | G141: =VLOOKUP(B141,EAN,3,0) -> 8435057017312 | H141: 3 x 100 ml | I141: 12 | J141: =D141/I141 -> 0 | K141: ='RESUMEN PEDIDO'!$C$29 -> 0 | L141: ='RESUMEN PEDIDO'!$C$30 -> 0 | M141: =(D141*(E141-(E141*K141)))-(D141*(E141-(E141*K141)))*L141 -> 0
B142: 513109 | C142: KINESSENCES COLOR 10.0 | E142: 36.9 | F142: 40.6 | G142: =VLOOKUP(B142,EAN,3,0) -> 8435057017329 | H142: 3 x 100 ml | I142: 12 | J142: =D142/I142 -> 0 | K142: ='RESUMEN PEDIDO'!$C$29 -> 0 | L142: ='RESUMEN PEDIDO'!$C$30 -> 0 | M142: =(D142*(E142-(E142*K142)))-(D142*(E142-(E142*K142)))*L142 -> 0
B143: 513110 | C143: KINESSENCES COLOR 6.02 | E143: 36.9 | F143: 40.6 | G143: =VLOOKUP(B143,EAN,3,0) -> 8435057017336 | H143: 3 x 100 ml | I143: 12 | J143: =D143/I143 -> 0 | K143: ='RESUMEN PEDIDO'!$C$29 -> 0 | L143: ='RESUMEN PEDIDO'!$C$30 -> 0 | M143: =(D143*(E143-(E143*K143)))-(D143*(E143-(E143*K143)))*L143 -> 0
B144: 513111 | C144: KINESSENCES COLOR 7.02 | E144: 36.9 | F144: 40.6 | G144: =VLOOKUP(B144,EAN,3,0) -> 8435057017343 | H144: 3 x 100 ml | I144: 12 | J144: =D144/I144 -> 0 | K144: ='RESUMEN PEDIDO'!$C$29 -> 0 | L144: ='RESUMEN PEDIDO'!$C$30 -> 0 | M144: =(D144*(E144-(E144*K144)))-(D144*(E144-(E144*K144)))*L144 -> 0
B145: 513112 | C145: KINESSENCES COLOR 8.02 | E145: 36.9 | F145: 40.6 | G145: =VLOOKUP(B145,EAN,3,0) -> 8435057017350 | H145: 3 x 100 ml | I145: 12 | J145: =D145/I145 -> 0 | K145: ='RESUMEN PEDIDO'!$C$29 -> 0 | L145: ='RESUMEN PEDIDO'!$C$30 -> 0 | M145: =(D145*(E145-(E145*K145)))-(D145*(E145-(E145*K145)))*L145 -> 0
... B200: 513167 | C200: KINESSENCES COLOR 6.77 | E200: 36.9 | F200: 40.6 | G200: =VLOOKUP(B200,EAN,3,0) -> 8435057017893 | H200: 3 x 100 ml | I200: 12 | J200: =D200/I200 -> 0 | K200: ='RESUMEN PEDIDO'!$C$29 -> 0 | L200: ='RESUMEN PEDIDO'!$C$30 -> 0 | M200: =(D200*(E200-(E200*K200)))-(D200*(E200-(E200*K200)))*L200 -> 0
B201: 513186 | C201: KINESSENCES COLOR LILAC | E201: 36.9 | F201: 40.6 | G201: 8435057019200 | H201: 3 x 100 ml | I201: 12 | J201: =D201/I201 -> 0 | K201: ='RESUMEN PEDIDO'!$C$29 -> 0 | L201: ='RESUMEN PEDIDO'!$C$30 -> 0 | M201: =(D201*(E201-(E201*K201)))-(D201*(E201-(E201*K201)))*L201 -> 0
B202: 513187 | C202: KINESSENCES COLOR STEEL | E202: 36.9 | F202: 40.6 | G202: 8435057019217 | H202: 3 x 100 ml | I202: 12 | J202: =D202/I202 -> 0 | K202: ='RESUMEN PEDIDO'!$C$29 -> 0 | L202: ='RESUMEN PEDIDO'!$C$30 -> 0 | M202: =(D202*(E202-(E202*K202)))-(D202*(E202-(E202*K202)))*L202 -> 0
B203: KINGLOSS COLOR / COLORACIÓN | D203: =SUM(D204:D222) -> 0 | I203: 36 | J203: =D203/I203 -> 0
B204: 560001 | C204: KINGLOSS COLOR 03.0 | E204: 9.2 | F204: 10.1 | G204: 8435057018654 | H204: 50 ml | I204: 12 | J204: =D204/I204 -> 0 | K204: ='RESUMEN PEDIDO'!$C$29 -> 0 | L204: ='RESUMEN PEDIDO'!$C$30 -> 0 | M204: =(D204*(E204-(E204*K204)))-(D204*(E204-(E204*K204)))*L204 -> 0
...

Sheet PRODUCTO REVENTA
B1: KIN COSMETICS, S.A.U.
B2: HOJA DE PEDIDO DISTRIBUIDOR
B6: PRODUCTO REVENTA
B7: SUBTOTAL PRODUCTO REVENTA | D7: =D9+D15+D20+D63+D81+D90+D99 -> 0 | J7: =J9+J15+J20+J63+J81+J90+J99 -> 0 | M7: =SUBTOTAL(9,M9:M100) -> 0
B8: Ref. | C8: Descripción | D8: Unidades | E8: Precio Tarifa | F8: PVP | G8: Código EAN | H8: Formato | I8: Packing | J8: Cajas | K8: Dto. 1% | L8: Dto. 2% | M8: Subtotal
B9: KINMEN / TRATAMIENTOS | D9: =SUM(D10:D14) -> 0 | J9: =SUM(J10:J14) -> 0
B10: 550077 | C10: KINMEN FORCE SHAMPOO | E10: 13 | F10: 14.3 | G10: =VLOOKUP(B10,EAN,3,0) -> 8435057016537 | H10: 300 ml | I10: 6 | J10: =D10/I10 -> 0 | K10: ='RESUMEN PEDIDO'!$C$29 -> 0 | L10: ='RESUMEN PEDIDO'!$C$30 -> 0 | M10: =(D10*(E10-(E10*K10)))-(D10*(E10-(E10*K10)))*L10 -> 0
B11: 550076 | C11: KINMEN SILVER SHAMPOO | E11: 13 | F11: 14.3 | G11: =VLOOKUP(B11,EAN,3,0) -> 8435057016520 | H11: 300 ml | I11: 6 | J11: =D11/I11 -> 0 | K11: ='RESUMEN PEDIDO'!$C$29 -> 0 | L11: ='RESUMEN PEDIDO'!$C$30 -> 0 | M11: =(D11*(E11-(E11*K11)))-(D11*(E11-(E11*K11)))*L11 -> 0
B12: 550075 | C12: KINMEN 3-IN-1 SHAMPOO | E12: 13 | F12: 14.3 | G12: =VLOOKUP(B12,EAN,3,0) -> 8435057016513 | H12: 300 ml | I12: 6 | J12: =D12/I12 -> 0 | K12: ='RESUMEN PEDIDO'!$C$29 -> 0 | L12: ='RESUMEN PEDIDO'!$C$30 -> 0 | M12: =(D12*(E12-(E12*K12)))-(D12*(E12-(E12*K12)))*L12 -> 0
B13: 550040 | C13: KINMEN FORCE TONIC | E13: 18 | F13: 19.8 | G13: =VLOOKUP(B13,EAN,3,0) -> 8435057013536 | H13: 125 ml | I13: 6 | J13: =D13/I13 -> 0 | K13: ='RESUMEN PEDIDO'!$C$29 -> 0 | L13: ='RESUMEN PEDIDO'!$C$30 -> 0 | M13: =(D13*(E13-(E13*K13)))-(D13*(E13-(E13*K13)))*L13 -> 0
B14: 550092 | C14: KINMEN BEARD CREAM | E14: 9 | F14: 9.9 | G14: 8435057020572 | H14: 50 ml | I14: 12 | J14: =D14/I14 -> 0 | K14: ='RESUMEN PEDIDO'!$C$29 -> 0 | L14: ='RESUMEN PEDIDO'!$C$30 -> 0 | M14: =(D14*(E14-(E14*K14)))-(D14*(E14-(E14*K14)))*L14 -> 0
B15: KINMEN / STYLING | D15: =SUM(D16:D19) -> 0 | J15: =SUM(J16:J19) -> 0
B16: 550078 | C16: KINMEN HAIR MATTE CLAY | E16: 15.5 | F16: 17.05 | G16: =VLOOKUP(B16,EAN,3,0) -> 8435057016544 | H16: 100 ml | I16: 6 | J16: =D16/I16 -> 0 | K16: ='RESUMEN PEDIDO'!$C$29 -> 0 | L16: ='RESUMEN PEDIDO'!$C$30 -> 0 | M16: =(D16*(E16-(E16*K16)))-(D16*(E16-(E16*K16)))*L16 -> 0
B17: 550079 | C17: KINMEN HAIR FIBER PASTE | E17: 15.5 | F17: 17.05 | G17: =VLOOKUP(B17,EAN,3,0) -> 8435057016551 | H17: 100 ml | I17: 6 | J17: =D17/I17 -> 0 | K17: ='RESUMEN PEDIDO'!$C$29 -> 0 | L17: ='RESUMEN PEDIDO'!$C$30 -> 0 | M17: =(D17*(E17-(E17*K17)))-(D17*(E17-(E17*K17)))*L17 -> 0
B18: 550084 | C18: KINMEN HAIR WET GEL | E18: 12 | F18: 13.2 | G18: =VLOOKUP(B18,EAN,3,0) -> 8435057016605 | H18: 150 ml | I18: 6 | J18: =D18/I18 -> 0 | K18: ='RESUMEN PEDIDO'!$C$29 -> 0 | L18: ='RESUMEN PEDIDO'!$C$30 -> 0 | M18: =(D18*(E18-(E18*K18)))-(D18*(E18-(E18*K18)))*L18 -> 0
B19: 550085 | C19: KINMEN POWER GEL | E19: 16.5 | F19: 18.15 | G19: =VLOOKUP(B19,EAN,3,0) -> 8435057016612 | H19: 150 ml | I19: 6 | J19: =D19/I19 -> 0 | K19: ='RESUMEN PEDIDO'!$C$29 -> 0 | L19: ='RESUMEN PEDIDO'!$C$30 -> 0 | M19: =(D19*(E19-(E19*K19)))-(D19*(E19-(E19*K19)))*L19 -> 0
B20: KINACTIF / TRATAMIENTOS | D20: =SUM(D21:D62) -> 0 | J20: =SUM(J21:J62) -> 0
B21: 511002 | C21: KINACTIF (Nº1 NUTRITION) DAILY MOISTURIZING SHAMPOO | E21: 14 | F21: 15.4 | G21: 8435057018012 | H21: 300 ml | I21: 6 | J21: =D21/I21 -> 0 | K21: ='RESUMEN PEDIDO'!$C$29 -> 0 | L21: ='RESUMEN PEDIDO'!$C$30 -> 0 | M21: =(D21*(E21-(E21*K21)))-(D21*(E21-(E21*K21)))*L21 -> 0
B22: 511004 | C22: KINACTIF (Nº1 NUTRITION) RICH NOURISHING SHAMPOO | E22: 14 | F22: 15.4 | G22: 8435057018036 | H22: 300 ml | I22: 6 | J22: =D22/I22 -> 0 | K22: ='RESUMEN PEDIDO'!$C$29 -> 0 | L22: ='RESUMEN PEDIDO'!$C$30 -> 0 | M22: =(D22*(E22-(E22*K22)))-(D22*(E22-(E22*K22)))*L22 -> 0
B23: 511006 | C23: KINACTIF (Nº1 NUTRITION) NOURISHING 2-IN-1 MASK | E23: 17.5 | F23: 19.25 | G23: 8435057018050 | H23: 200 ml | I23: 6 | J23: =D23/I23 -> 0 | K23: ='RESUMEN PEDIDO'!$C$29 -> 0 | L23: ='RESUMEN PEDIDO'!$C$30 -> 0 | M23: =(D23*(E23-(E23*K23)))-(D23*(E23-(E23*K23)))*L23 -> 0
B24: 511009 | C24: KINACTIF (Nª1 NUTRITION) MOISTURIZING CONDITIONING SPRAY | E24: 13.6 | F24: 14.95 | G24: 8435057018081 | H24: 200 ml | I24: 6 | J24: =D24/I24 -> 0 | K24: ='RESUMEN PEDIDO'!$C$29 -> 0 | L24: ='RESUMEN PEDIDO'!$C$30 -> 0 | M24: =(D24*(E24-(E24*K24)))-(D24*(E24-(E24*K24)))*L24 -> 0
B25: 511010 | C25: KINACTIF (Nª1 NUTRITION) NOURISHING MELTING EXTRACT | E25: 16.4 | F25: 18.05 | G25: 8435057018098 | H25: 150 ml | I25: 6 | J25: =D25/I25 -> 0 | K25: ='RESUMEN PEDIDO'!$C$29 -> 0 | L25: ='RESUMEN PEDIDO'!$C$30 -> 0 | M25: =(D25*(E25-(E25*K25)))-(D25*(E25-(E25*K25)))*L25 -> 0
B26: 511149 | C26: KINACTIF (Nº1 NUTRITION) MOISTURIZING PACK (SHAMPOO + MASK + M. SPRAY) | E26: 45.1 | F26: 49.6 | G26: 8435057020411 | H26: 300 ml + 200 ml + 200 ml | I26: 6 | J26: =D26/I26 -> 0 | K26: ='RESUMEN PEDIDO'!$C$29 -> 0 | L26: ='RESUMEN PEDIDO'!$C$30 -> 0 | M26: =(D26*(E26-(E26*K26)))-(D26*(E26-(E26*K26)))*L26 -> 0
B27: 511150 | C27: KINACTIF (Nº1 NUTRITION) NOURISHING PACK (SHAMPOO + MASK + M. EXTRACT) | E27: 47.9 | F27: 52.7 | G27: 8435057020428 | H27: 300 ml + 200 ml + 150 ml | I27: 6 | J27: =D27/I27 -> 0 | K27: ='RESUMEN PEDIDO'!$C$29 -> 0 | L27: ='RESUMEN PEDIDO'!$C$30 -> 0 | M27: =(D27*(E27-(E27*K27)))-(D27*(E27-(E27*K27)))*L27 -> 0
B28: 511011 | C28: KINACTIF (Nº2 REPAIR) RICH RECONSTRUCTING SHAMPOO | E28: 14 | F28: 15.4 | G28: 8435057018104 | H28: 300 ml | I28: 6 | J28: =D28/I28 -> 0 | K28: ='RESUMEN PEDIDO'!$C$29 -> 0 | L28: ='RESUMEN PEDIDO'!$C$30 -> 0 | M28: =(D28*(E28-(E28*K28)))-(D28*(E28-(E28*K28)))*L28 -> 0
B29: 511013 | C29: KINACTIF (Nº2 REPAIR) RECONSTRUCTING 2-IN-1 MASK | E29: 17.5 | F29: 19.25 | G29: 8435057018128 | H29: 200 ml | I29: 6 | J29: =D29/I29 -> 0 | K29: ='RESUMEN PEDIDO'!$C$29 -> 0 | L29: ='RESUMEN PEDIDO'!$C$30 -> 0 | M29: =(D29*(E29-(E29*K29)))-(D29*(E29-(E29*K29)))*L29 -> 0
B30: 511016 | C30: KINACTIF (Nº2 REPAIR) RECONSTRUCTING MELTING EXTRACT | E30: 16.4 | F30: 18.05 | G30: 8435057018159 | H30: 150 ml | I30: 6 | J30: =D30/I30 -> 0 | K30: ='RESUMEN PEDIDO'!$C$29 -> 0 | L30: ='RESUMEN PEDIDO'!$C$30 -> 0 | M30: =(D30*(E30-(E30*K30)))-(D30*(E30-(E30*K30)))*L30 -> 0
B31: 511151 | C31: KINACTIF (Nº2 REPAIR) PACK (SHAMPOO + MASK + M. EXTRACT) | E31: 47.9 | F31: 52.7 | G31: 8435057020435 | H31: 300 ml + 200 ml + 150 ml | I31: 6 | J31: =D31/I31 -> 0 | K31: ='RESUMEN PEDIDO'!$C$29 -> 0 | L31: ='RESUMEN PEDIDO'!$C$30 -> 0 | M31: =(D31*(E31-(E31*K31)))-(D31*(E31-(E31*K31)))*L31 -> 0
B32: 511017 | C32: KINACTIF (Nº3 VOLUME) MILD EXPANDING SHAMPOO | E32: 14 | F32: 15.4 | G32: 8435057018166 | H32: 300 ml | I32: 6 | J32: =D32/I32 -> 0 | K32: ='RESUMEN PEDIDO'!$C$29 -> 0 | L32: ='RESUMEN PEDIDO'!$C$30 -> 0 | M32: =(D32*(E32-(E32*K32)))-(D32*(E32-(E32*K32)))*L32 -> 0
B33: 511019 | C33: KINACTIF (Nº3 VOLUME) EXPANDING 2-IN-1 MASK | E33: 17.5 | F33: 19.25 | G33: 8435057018180 | H33: 200 ml | I33: 6 | J33: =D33/I33 -> 0 | K33: ='RESUMEN PEDIDO'!$C$29 -> 0 | L33: ='RESUMEN PEDIDO'!$C$30 -> 0 | M33: =(D33*(E33-(E33*K33)))-(D33*(E33-(E33*K33)))*L33 -> 0
B34: 511020 | C34: KINACTIF (Nº3 VOLUME) EXPANDING ROOT FOAM | E34: 15.3 | F34: 16.85 | G34: 8435057018197 | H34: 150 ml | I34: 6 | J34: =D34/I34 -> 0 | K34: ='RESUMEN PEDIDO'!$C$29 -> 0 | L34: ='RESUMEN PEDIDO'!$C$30 -> 0 | M34: =(D34*(E34-(E34*K34)))-(D34*(E34-(E34*K34)))*L34 -> 0
B35: 511152 | C35: KINACTIF (Nº3 VOLUME) PACK (SHAMPOO + MASK + R. FOAM) | E35: 46.8 | F35: 51.5 | G35: 8435057020442 | H35: 300 ml + 200 ml + 150 ml | I35: 6 | J35: =D35/I35 -> 0 | K35: ='RESUMEN PEDIDO'!$C$29 -> 0 | L35: ='RESUMEN PEDIDO'!$C$30 -> 0 | M35: =(D35*(E35-(E35*K35)))-(D35*(E35-(E35*K35)))*L35 -> 0
B36: 511047 | C36: KINACTIF (Nº4 COLOR) COLOR PROTECTING SHAMPOO | E36: 14 | F36: 15.4 | G36: 8435057019019 | H36: 300 ml | I36: 6 | J36: =D36/I36 -> 0 | K36: ='RESUMEN PEDIDO'!$C$29 -> 0 | L36: ='RESUMEN PEDIDO'!$C$30 -> 0 | M36: =(D36*(E36-(E36*K36)))-(D36*(E36-(E36*K36)))*L36 -> 0
B37: 511051 | C37: KINACTIF (Nº4 COLOR) COLOR PROTECTING 2-IN-1 MASK | E37: 17.5 | F37: 19.25 | G37: 8435057019057 | H37: 200 ml | I37: 6 | J37: =D37/I37 -> 0 | K37: ='RESUMEN PEDIDO'!$C$29 -> 0 | L37: ='RESUMEN PEDIDO'!$C$30 -> 0 | M37: =(D37*(E37-(E37*K37)))-(D37*(E37-(E37*K37)))*L37 -> 0
B38: 511055 | C38: KINACTIF (Nº4 COLOR) COLOR PROTECTING MELTING EXTRACT | E38: 16.4 | F38: 18.05 | G38: 8435057019095 | H38: 150 ml | I38: 6 | J38: =D38/I38 -> 0 | K38: ='RESUMEN PEDIDO'!$C$29 -> 0 | L38: ='RESUMEN PEDIDO'!$C$30 -> 0 | M38: =(D38*(E38-(E38*K38)))-(D38*(E38-(E38*K38)))*L38 -> 0
B39: 511153 | C39: KINACTIF (Nº4 COLOR) PACK (SHAMPOO + MASK + M. EXTRACT) | E39: 47.9 | F39: 52.7 | G39: 8435057020459 | H39: 300 ml + 200 ml + 150 ml | I39: 6 | J39: =D39/I39 -> 0 | K39: ='RESUMEN PEDIDO'!$C$29 -> 0 | L39: ='RESUMEN PEDIDO'!$C$30 -> 0 | M39: =(D39*(E39-(E39*K39)))-(D39*(E39-(E39*K39)))*L39 -> 0
B40: 511049 | C40: KINACTIF (Nº5 BLONDE) ANTI-BRASS BLONDE SHAMPOO | E40: 14 | F40: 15.4 | G40: 8435057019033 | H40: 300 ml | I40: 6 | J40: =D40/I40 -> 0 | K40: ='RESUMEN PEDIDO'!$C$29 -> 0 | L40: ='RESUMEN PEDIDO'!$C$30 -> 0 | M40: =(D40*(E40-(E40*K40)))-(D40*(E40-(E40*K40)))*L40 -> 0
B41: 511053 | C41: KINACTIF (Nº5 BLONDE) ANTI-BRASS BLONDE MASK | E41: 17.5 | F41: 19.25 | G41: 8435057019071 | H41: 200 ml | I41: 6 | J41: =D41/I41 -> 0 | K41: ='RESUMEN PEDIDO'!$C$29 -> 0 | L41: ='RESUMEN PEDIDO'!$C$30 -> 0 | M41: =(D41*(E41-(E41*K41)))-(D41*(E41-(E41*K41)))*L41 -> 0
B42: 511021 | C42: KINACTIF (Nº6 SUNCARE) AFTERSUN SHAMPOO & SHOWER GEL | E42: 14 | F42: 15.4 | G42: 8435057018203 | H42: 300 ml | I42: 6 | J42: =D42/I42 -> 0 | K42: ='RESUMEN PEDIDO'!$C$29 -> 0 | L42: ='RESUMEN PEDIDO'!$C$30 -> 0 | M42: =(D42*(E42-(E42*K42)))-(D42*(E42-(E42*K42)))*L42 -> 0
B43: 511022 | C43: KINACTIF (Nº6 SUNCARE) AFTERSUN 2-IN-1 MASK | E43: 17 | F43: 18.7 | G43: 8435057018210 | H43: 200 ml | I43: 6 | J43: =D43/I43 -> 0 | K43: ='RESUMEN PEDIDO'!$C$29 -> 0 | L43: ='RESUMEN PEDIDO'!$C$30 -> 0 | M43: =(D43*(E43-(E43*K43)))-(D43*(E43-(E43*K43)))*L43 -> 0
...

Sheet MATERIAL MARKETING
B1: KIN COSMETICS, S.A.U.
B2: HOJA DE PEDIDO DISTRIBUIDOR | F2: CRÉDITO | H2: ='[1]RESUMEN PEDIDO'!H41 -> 0
F3: DIFERENCIA | H3: ='RESUMEN PEDIDO'!H45 -> 0
B6: MATERIAL MARKETING
B7: SUBTOTAL MATERIAL MARKETING | D7: =SUBTOTAL(9,D9:D147) -> 0 | H7: =SUBTOTAL(9,H9:H147) -> 0
B8: Ref. | C8: Descripción | D8: Unidades | E8: Precio Tarifa | F8: Formato | G8: Dto. | H8: Subtotal
B9: MATERIAL PROMOCIONAL / DESECHABLES
B10: 310255 | C10: CAPAS DESECHABLES KIN WE LOVE HAIR | E10: 17.07619 | F10: Caja 50 uds. | G10: ='[1]RESUMEN PEDIDO'!$C$31 -> 0.7 | H10: =(D10*(E10-(E10*G10))) -> 0
B11: 310280 | C11: GORROS DESECHABLES MECHAS KIN WE LOVE HAIR (*) | E11: 6.9840048 | F11: Bolsa 50 uds. | G11: ='[1]RESUMEN PEDIDO'!$C$31 -> 0.7 | H11: =(D11*(E11-(E11*G11))) -> 0
B12: MATERIAL PROMOCIONAL / ELÉCTRICOS
B13: 310388 | C13: PLANCHA PROFESIONAL KIN LATTE EDITION | E13: 96.904762 | F13: Unidad | G13: ='[1]RESUMEN PEDIDO'!$C$31 -> 0.7 | H13: =(D13*(E13-(E13*G13))) -> 0
B14: MATERIAL PROMOCIONAL / UTENSILIOS
B15: 310148 | C15: BOL COLORACIÓN KIN NEGRO | E15: 1.7652381 | F15: Unidad | G15: ='[1]RESUMEN PEDIDO'!$C$31 -> 0.7 | H15: =(D15*(E15-(E15*G15))) -> 0
B16: 310326 | C16: PALETINA COLOR KIN NEGRA - TALLA M | E16: 1.8333333 | F16: Unidad | G16: ='[1]RESUMEN PEDIDO'!$C$31 -> 0.7 | H16: =(D16*(E16-(E16*G16))) -> 0
B17: 310327 | C17: PALETINA COLOR KIN NEGRA - TALLA L | E17: 1.8333333 | F17: Unidad | G17: ='[1]RESUMEN PEDIDO'!$C$31 -> 0.7 | H17: =(D17*(E17-(E17*G17))) -> 0
B18: 310362 | C18: BOTELLA APLICADORA COLOR KIN | E18: 4.3140952 | F18: Unidad | G18: ='[1]RESUMEN PEDIDO'!$C$31 -> 0.7 | H18: =(D18*(E18-(E18*G18))) -> 0
B19: 310352 | C19: BOL TRATAMIENTOS KIN BLANCO | E19: 6.2857143 | F19: Unidad | G19: ='[1]RESUMEN PEDIDO'!$C$31 -> 0.7 | H19: =(D19*(E19-(E19*G19))) -> 0
B20: 310353 | C20: PALETINA TRATAMIENTOS KIN BLANCA | E20: 1.3095238 | F20: Unidad | G20: ='[1]RESUMEN PEDIDO'!$C$31 -> 0.7 | H20: =(D20*(E20-(E20*G20))) -> 0
B21: 310400 | C21: ESPATULA TRATAMIENTOS KIN | E21: 0.62857143 | F21: Unidad | G21: ='[1]RESUMEN PEDIDO'!$C$31 -> 0.7 | H21: =(D21*(E21-(E21*G21))) -> 0
B22: 310393 | C22: CEPILLO MASAJEADOR DE CUERO CABELLUDO KIN | E22: 3.352381 | F22: Unidad | G22: ='[1]RESUMEN PEDIDO'!$C$31 -> 0.7 | H22: =(D22*(E22-(E22*G22))) -> 0
B23: 310392 | C23: PEINE MECHAS KIN BABYLIGHTS | E23: 2.7238095 | F23: Unidad | G23: ='[1]RESUMEN PEDIDO'!$C$31 -> 0.7 | H23: =(D23*(E23-(E23*G23))) -> 0
B24: 310355 | C24: CAPA DE CORTE KIN NEGRA | E24: 25.195238 | F24: Unidad | G24: ='[1]RESUMEN PEDIDO'!$C$31 -> 0.7 | H24: =(D24*(E24-(E24*G24))) -> 0
B25: 310244 | C25: ESPEJO KIN WE LOVE HAIR (*) | E25: 13.357143 | F25: Unidad | G25: ='[1]RESUMEN PEDIDO'!$C$31 -> 0.7 | H25: =(D25*(E25-(E25*G25))) -> 0
B26: 310328 | C26: VÁLVULA SHAMPOO 1.000 ML KINACTIF | E26: 1.1561 | F26: Unidad | G26: ='[1]RESUMEN PEDIDO'!$C$31 -> 0.7 | H26: =(D26*(E26-(E26*G26))) -> 0
... B31: 310332 | C31: TAPÓN DOSIFICADOR NEGRO OXIDANTES / DEVELOPERS 1.000 ML | E31: 0.25698095 | F31: Unidad | G31: ='[1]RESUMEN PEDIDO'!$C$31 -> 0.7 | H31: =(D31*(E31-(E31*G31))) -> 0
B32: MATERIAL PROMOCIONAL / COMUNICACIÓN
B33: 300865 | C33: CATÁLOGO PRODUCT PORTFOLIO (Edición Marzo 2025) | E33: 4.5204762 | F33: A4 | G33: ='[1]RESUMEN PEDIDO'!$C$31 -> 0.7 | H33: =(D33*(E33-(E33*G33))) -> 0
B34: 300909 | C34: TARIFA PVP 2026 | E34: 1.87 | F34: 24 x 14,5 cm | G34: ='[1]RESUMEN PEDIDO'!$C$31 -> 0.7 | H34: =(D34*(E34-(E34*G34))) -> 0
B35: 300904 | C35: DOOR STICKER KIN COSMÉTICA DE PROXIMIDAD | E35: 5.222381 | F35: Ø 24 cm | G35: ='[1]RESUMEN PEDIDO'!$C$31 -> 0.7 | H35: =(D35*(E35-(E35*G35))) -> 0
B36: 300710 | C36: CARTA COLOR KINCREM COLOR - 120 TONOS | E36: 71.395238 | F36: 40 x 24 cm | G36: ='[1]RESUMEN PEDIDO'!$C$31 -> 0.7 | H36: =(D36*(E36-(E36*G36))) -> 0
B37: 300714 | C37: QUICK COLOR GUIDE KINCREM COLOR (*) | E37: 2.5525238 | F37: A4 | G37: ='[1]RESUMEN PEDIDO'!$C$31 -> 0.7 | H37: =(D37*(E37-(E37*G37))) -> 0
B38: 300716 | C38: FOLDER TÉCNICO KINCREM COLOR | E38: 4.3144095 | F38: A4 | G38: ='[1]RESUMEN PEDIDO'!$C$31 -> 0.7 | H38: =(D38*(E38-(E38*G38))) -> 0
B39: 300732 | C39: BANNER TEXTIL KINCREM COLOR MODELO 2 (*) | E39: 40.912824 | F39: 50 x 110 cm | G39: ='[1]RESUMEN PEDIDO'!$C$31 -> 0.7 | H39: =(D39*(E39-(E39*G39))) -> 0
B40: 300883 | C40: FOLDER TÉCNICO MOCHA MOUSSE COLLECTION by KINCREM COLOR (*) | E40: 3.6142857 | F40: A4 | G40: ='[1]RESUMEN PEDIDO'!$C$31 -> 0.7 | H40: =(D40*(E40-(E40*G40))) -> 0
B41: 300829 | C41: CARTA COLOR KINESSENCES COLOR VEGAN - 69 TONOS | E41: 68.042857 | F41: 24 x 40 cm | G41: ='[1]RESUMEN PEDIDO'!$C$31 -> 0.7 | H41: =(D41*(E41-(E41*G41))) -> 0
B42: 300761 | C42: QUICK COLOR GUIDE KINESSENCES COLOR VEGAN (*) | E42: 2.9333333 | F42: A4 | G42: ='[1]RESUMEN PEDIDO'!$C$31 -> 0.7 | H42: =(D42*(E42-(E42*G42))) -> 0
B43: 300762 | C43: FOLDER TÉCNICO KINESSENCES COLOR VEGAN | E43: 3.5457714 | F43: 1 | G43: ='[1]RESUMEN PEDIDO'!$C$31 -> 0.7 | H43: =(D43*(E43-(E43*G43))) -> 0
B44: 300759 | C44: DOOR STICKER KINESSENCES COLOR VEGAN (*) | E44: 20.577333 | F44: Ø 24 cm | G44: ='[1]RESUMEN PEDIDO'!$C$31 -> 0.7 | H44: =(D44*(E44-(E44*G44))) -> 0
B45: 300783 | C45: VINILO CHICA KINESSENCES COLOR (*) | E45: 28.432381 | F45: 90 x 65 cm | G45: ='[1]RESUMEN PEDIDO'!$C$31 -> 0.7 | H45: =(D45*(E45-(E45*G45))) -> 0
B46: 300832 | C46: CARTA COLOR KINGLOSS COLOR | E46: 54.47619 | F46: 35,6 x 16,2 cm | G46: ='[1]RESUMEN PEDIDO'!$C$31 -> 0.7 | H46: =(D46*(E46-(E46*G46))) -> 0
...

Sheet PRODUCTO OUTLET
B1: KIN COSMETICS, S.A.U.
B2: HOJA DE PEDIDO DISTRIBUIDOR
B6: PRODUCTO OUTLET
B7: SUBTOTAL PRODUCTO OUTLET | D7: =D9+D13+D17 -> 0 | I7: =I9+I13+I17 -> 0 | J7: =SUBTOTAL(9,J9:J23) -> 0
B8: Ref. | C8: Descripción | D8: Unidades | E8: Precio Neto | F8: Código EAN | G8: Formato | H8: Packing | I8: Cajas | J8: Subtotal
B9: EARTH NUDES COLLECTION BY KINCREM PRESTIGE / COLORACIÓN | D9: =SUM(D10:D12) -> 0 | H9: 36 | I9: =SUM(I10:I12) -> 0
B10: 501140 | C10: EARTH NUDES COLLECTION 7.512 SAHARA NUDE | E10: 3.6 | F10: =VLOOKUP(B10,EAN,3,0) -> 8435057014021 | G10: 3 x 60 ml | H10: 36 | I10: =D10/H10 -> 0 | J10: =D10*E10 -> 0
B11: 501141 | C11: EARTH NUDES COLLECTION 8.348 NAMBUNG OCHER | E11: 3.6 | F11: =VLOOKUP(B11,EAN,3,0) -> 8435057014038 | G11: 3 x 60 ml | H11: 36 | I11: =D11/H11 -> 0 | J11: =D11*E11 -> 0
B12: 501142 | C12: EARTH NUDES COLLECTION 8.762 JORDAN ROSE | E12: 3.6 | F12: =VLOOKUP(B12,EAN,3,0) -> 8435057014045 | G12: 3 x 60 ml | H12: 36 | I12: =D12/H12 -> 0 | J12: =D12*E12 -> 0
B13: RUST COLLECTION BY KINESSENCES COLOR / COLORACIÓN | D13: =SUM(D14:D16) -> 0 | H13: 36 | I13: =D13/H13 -> 0
B14: 512183 | C14: RUST COLLECTION 5.519 ASHY BROWN | E14: 3.5 | F14: =VLOOKUP(B14,EAN,3,0) -> 8435057014694 | G14: 3 x 60 ml | H14: 36 | I14: =D14/H14 -> 0 | J14: =D14*E14 -> 0
B15: 512184 | C15: RUST COLLECTION 6.762 PURPLE DUST | E15: 3.5 | F15: =VLOOKUP(B15,EAN,3,0) -> 8435057014700 | G15: 3 x 60 ml | H15: 36 | I15: =D15/H15 -> 0 | J15: =D15*E15 -> 0
B16: 512185 | C16: RUST COLLECTION 7.456 OXIDE AMBER | E16: 3.5 | F16: =VLOOKUP(B16,EAN,3,0) -> 8435057014717 | G16: 3 x 60 ml | H16: 36 | I16: =D16/H16 -> 0 | J16: =D16*E16 -> 0
B17: KINACTIF / TRATAMIENTOS | D17: =SUM(D18:D23) -> 0 | I17: =SUM(I18:I19) -> 0
B18: 510142 | C18: KINACTIF ENERGY RECONSTRUCTOR | E18: 4 | F18: 8435057006767 | G18: 150 ml | H18: 6 | I18: =D18/H18 -> 0 | J18: =D18*E18 -> 0
B19: 510161 | C19: KINACTIF NUTRI SERUM | E19: 4.5 | F19: =VLOOKUP(B19,EAN,3,0) -> 8435057006958 | G19: 50 ml | H19: 6 | I19: =D19/H19 -> 0 | J19: =D19*E19 -> 0
B20: 510170 | C20: KINACTIF FORCE COMPLEXE TRICO-ACTIVE (*) | E20: 14.7 | F20: 8435057007047 | G20: 12 x 6 ml | H20: 6 | I20: =D20/H20 -> 0 | J20: =D20*E20 -> 0
B21: 510175 | C21: KINACTIF PURITY TONIC | E21: 4.5 | F21: 8435057007092 | G21: 150 ml | H21: 6 | I21: =D21/H21 -> 0 | J21: =D21*E21 -> 0
B22: 510179 | C22: KINACTIF BALANCE TONIC | E22: 4.5 | F22: 8435057007146 | G22: 150 ml | H22: 6 | I22: =D22/H22 -> 0 | J22: =D22*E22 -> 0
B23: 510332 | C23: KINACTIF CALM SHAMPOO | E23: 2.8 | F23: 8435057015158 | G23: 300 ml | H23: 6 | I23: =D23/H23 -> 0 | J23: =D23*E23 -> 0
B24: Precios netos (no aplican descuentos). Todos los artículos son hasta fin de existencias

Sheet MATERIAL MKT OUTLET
B1: KIN COSMETICS, S.A.U.
B2: HOJA DE PEDIDO DISTRIBUIDOR | F2: CRÉDITO | G2: ='RESUMEN PEDIDO'!H54 -> 0
F3: DIFERENCIA | G3: ='RESUMEN PEDIDO'!H58 -> 0
B6: MATERIAL MARKETING OUTLET
B7: SUBTOTAL MATERIAL MARKETING OUTLET | D7: =SUBTOTAL(9,D10:D29) -> 0 | G7: =SUBTOTAL(9,G10:G29) -> 0
B8: Ref. | C8: Descripción | D8: Unidades | E8: Precio Outlet | F8: Formato | G8: Subtotal
B9: MATERIAL PROMOCIONAL / UTENSILIOS
B10: 390015 | C10: PACK 4 PINZAS SILICONA ROSA FRAMAR | E10: 3.32 | F10: Unidad | G10: =E10*D10 -> 0
B11: MATERIAL PROMOCIONAL / COMUNICACIÓN
B12: 300640 | C12: CARTA EARTH NUDES COLLECTION BY KINCREM PRESTIGE | E12: 6.02 | F12: 18 x 28 cm | G12: =E12*D12 -> 0
B13: 300641 | C13: KIT PRESENTACIÓN EARTH NUDES COLLECTION BY KINCREM PRESTIGE (prod. incl.) | E13: 7.03 | F13: 26,5 x 22,5 x 3 cm | G13: =E13*D13 -> 0
B14: 300643 | C14: DISPLAY DOBLE ALA EARTH NUDES COLLECTION BY KINCREM PRESTIGE | E14: 2.49 | F14: 66 x 96 cm | G14: =E14*D14 -> 0
B15: 300521 | C15: CARTA COLOR KINESSENCES COLOR | E15: 12.46 | F15: 24 x 40 cm | G15: =E15*D15 -> 0
B16: 300524 | C16: KINESSENCES COLOR QUICK COLOR GUIDE | E16: 0.39 | F16: A4 | G16: =E16*D16 -> 0
B17: 300549 | C17: FOLLETO KINESSENCES DETOX RETAIL | E17: 0.04 | F17: 10,5 x 15 cm | G17: =E17*D17 -> 0
B18: 300636 | C18: FOLDER TÉCNICO KINESSENCES RESTORE | E18: 0.62 | F18: A4 | G18: =E18*D18 -> 0
B19: 300639 | C19: FOLLETO MINI KINESSENCES RESTORE | E19: 0.08 | F19: 8 x 10 cm | G19: =E19*D19 -> 0
B20: 300735 | C20: DIPTICO KINESSENCES RESTORE RETAIL | E20: 0.1 | F20: A4 | G20: =E20*D20 -> 0
B21: 300733 | C21: DIPTICO KINACTIF FORCE RETAIL | E21: 0.1 | F21: A4 | G21: =E21*D21 -> 0
B22: 300674 | C22: CARTA RUST COLLECTION BY KINESSENCES COLOR | E22: 3.56 | F22: 18 x 28 cm | G22: =E22*D22 -> 0
B23: 300675 | C23: KIT PRESENTACIÓN RUST COLLECTION BY KINESSENCES COLOR (prod. incl.) | E23: 8.635 | F23: 26,5 x 22,5 x 3 cm | G23: =E23*D23 -> 0
B24: 300690 | C24: FOLDER TÉCNICO RUST COLLECTION | E24: 0.2288 | F24: A4 | G24: =E24*D24 -> 0
B25: 300677 | C25: DISPLAY DOBLE ALA RUST COLLECTION BY KINESSENCES COLOR | E25: 2.32 | F25: 66 x 96 cm | G25: =E25*D25 -> 0
B26: MATERIAL PROMOCIONAL / REVENTA
B27: 510236 | C27: SACHET CALM SHAMPOO | E27: 0.2 | F27: 8 ml | G27: =E27*D27 -> 0
B28: 310279 | C28: BOLSA REVENTA KINESSENCES RESTORE | E28: 0.53 | F28: Unidad | G28: =E28*D28 -> 0
B29: 310340 | C29: COOLER BAG KINACTIF SUNCARE | E29: 2.83 | F29: 34 x 21 x 26 cm | G29: =E29*D29 -> 0
B30: Todos los artículos son hasta fin de existencias.

Sheet EAN
A1: CÓDIGOS EAN
A3: Nº producto | B3: Descripción Producto | C3: Nº referencia cruzada
A4: 11000 | B4: AGUA DESIONIZADA Lts. | C4: LIAGUA
A5: 11001 | B5: CARBOPOL 980 | C5: SPC940
A6: 11002 | B6: EASYCOL ES27 | C6: TESDSS
A7: 11002 | B7: EASYCOL ES27 | C7: 11002
A8: 11002 | B8: EASYCOL ES27 | C8: 11002
A9: 11003 | B9: DABEERSEN NA4 C2 / NA4 TD | C9: CNDANA
A10: 11003 | B10: DABEERSEN NA4 C2 / NA4 TD | C10: CNDANA
A11: 11004 | B11: JAGUAR C-13 SH | C11: POJA13
A12: 11005 | B12: EASYLAN LS / NEOWAX SX/W | C12: 11005
A13: 11005 | B13: EASYLAN LS / NEOWAX SX/W | C13: 11005
A14: 11005 | B14: EASYLAN LS / NEOWAX SX/W | C14: 11005
A15: 11006 | B15: MIRASIL 60000 | C15: MIRASIL 60000
... A350: 11359 | B350: DAPRACARE GMS-35-SE | C350: 11359
A351: 11381 | B351: QUINOA PRO NPNF
A352: 11401 | B352: DAPRACARE GMS 35 SE (ES 11359) | C352: 11401
A353: 11401 | B353: DAPRACARE GMS 35 SE (ES 11359) | C353: 11401
A354: 12000 | B354: RESORCINOL TECH.GRADE FLAKES | C354: RODOL
A355: 12000 | B355: RESORCINOL TECH.GRADE FLAKES | C355: JARCOCOL
A356: 12000 | B356: RESORCINOL TECH.GRADE FLAKES | C356: CORESO
A357: 12000 | B357: RESORCINOL TECH.GRADE FLAKES | C357: CORESO
A358: 12001 | B358: RODOL 4BXN | C358: CO4BXN
A359: 12002 | B359: LOWACRYL BLUE 7 | C359: COBLU7
A360: 12003 | B360: LOWACRYL BLUE 9 | C360: COBLU9
A361: 12004 | B361: RODOL GRAY HED | C361: COGRHE
A362: 12004 | B362: RODOL GRAY HED | C362: COGRHE
A363: 12005 | B363: HC BLUE 2 CP | C363: COHCB2
... A525: 13089 | B525: PERFUME AMBER 2004747 | C525: PFAMBE
A526: 13090 | B526: PERFUME NIPPER FRESH 5470K
A527: 13091 | B527: PERF FRESH BALSAM INC.2004858 | C527: PFFRBA
A528: 13092 | B528: PERFUME NATURAL 2005388 | C528: PFNATU
A529: 13093 | B529: PERFUME IRIS TINT 30130 | C529: PFIRTI
A530: 13094 | B530: PERF. SH.NEW MARACUYA 21394 | C530: PFNEMASH
A531: 13095 | B531: PERF. SH. TEI ORANGE 12072 | C531: PFTEORSH
A532: 13096 | B532: HAVEN | C532: PFHAVE
A533: 13097 | B533: CUHERBAL 1104980 | C533: PFCUHE
A534: 13098 | B534: HERBALFRESH 1119950 | C534: PFHERB
A535: 13099 | B535: COOL M 2005072 | C535: PFCOOL
A536: 13100 | B536: COOL BLUE 17673 | C536: PFCLBL
...

Sheet BBDD ACTUALITZADA
A1: Nº | B1: Nombre | C1: CIF/NIF | D1: Dirección | E1: C.P. | F1: Población | G1: Provincia | H1: Nº teléfono | I1: Correo electrónico | J1: Cód. vendedor | K1: Importe Contrato Técnico | L1: Grupo registro IVA neg. | M1: Cód. términos pago | N1: Cód. Ruta | O1: Cód. transportista
A2: 9 | B2: DIST.CAROBEL'S CATALUÑA, S.L. | C2: B59945725 | D2: CL RELOJ, 7-9 | E2: 08923 | F2: SANTA COLOMA DE GRAMENET | G2: BARCELONA | H2: +34 933929352 | I2: distribucionescarobels@gmail.com | J2: 1004D | K2: 0 | L2: NACIONAL | M2: 4 | N2: PRL-900-11 | O2: 26 | P2: ES | Q2: NOEL BLANCO CURSA
A3: 31 | B3: EXCLUSIVAS NEGREDO S.L. | C3: B20223178 | D3: CL/ IRIBAR 6 C8-C9 POL.A.E. NEINOR | E3: 20018 | F3: GUIPUZCOA | G3: GUIPUZCOA | H3: +34 943492554 | I3: administracion@negredoprofesional.com; gerencia@negredoprofesional.com | J3: 1004D | K3: 0 | L3: NACIONAL | M3: 4 | N3: NOR-900-11 | O3: 22 | P3: ES | Q3: NOEL BLANCO CURSA
A4: 79 | B4: COMERCIAL PUJANTE S.L. | C4: B30094338 | D4: CL JUAN HERNÁNDEZ GONZÁLEZ, 2 | E4: 30565 | F4: LAS TORRES DE COTILLAS | G4: MURCIA | H4: +34 968620088 | I4: rafael.martinez@comercialpujante.com | J4: 1004D | K4: 0 | L4: NACIONAL | M4: 4 | N4: SUR-900-11 | O4: 22 | P4: ES | Q4: NOEL BLANCO CURSA
A5: 102 | B5: EXCLUSIVAS LADY'S S.L. | C5: B18089235 | D5: CL CASTILLA 39-40 | E5: 18210 | F5: PELIGROS | G5: GRANADA | H5: +34 958400177 | I5: plopez@exclusivasladys.com; info@exclusivasladys.com | J5: 1004D | K5: 0 | L5: NACIONAL | M5: 4 | N5: SUR-900-11 | O5: 22 | P5: ES | Q5: NOEL BLANCO CURSA
A6: 106 | B6: LARA SANCHEZ, FRANCISCO | C6: 34010807V | D6: AV LAS VENTAS 35 | E6: 14910 | F6: BENAMEJI | G6: CORDOBA | H6: +34 629888997 | I6: dislapefla@hotmail.com | J6: 1004D | K6: 0 | L6: NACIONAL | M6: 1-2PP | N6: SUR-900-11 | O6: 22 | P6: ES | Q6: NOEL BLANCO CURSA
A7: 155 | B7: EXCLUSIVAS J.J. SANCHEZ, S.L. | C7: B33805110 | D7: CL CORTES DE CADIZ 6 BIS BJ | E7: 33212 | F7: GIJON | G7: ASTURIAS | H7: +34 985338175 | I7: exclusivasjjsanchez@gmail.com | J7: 1004D | K7: 0 | L7: NACIONAL | M7: 4 | N7: NOR-900-11 | O7: 10 | P7: ES | Q7: NOEL BLANCO CURSA
A8: 199 | B8: COMERCIAL LOMARK, S.C.P. | C8: J60955119 | D8: CL/ CARRIL,17-19,4-BIS | E8: 08750 | F8: MOLINS DE REI | G8: BARCELONA | H8: +34 936683653 | I8: comerciallomark@gmail.com | J8: 1004D | K8: 0 | L8: NACIONAL | M8: 4 | N8: PRL-900-11 | O8: 26 | P8: ES | Q8: NOEL BLANCO CURSA
A9: 500 | B9: CEBRIAN, C.B. | C9: E02243426 | D9: CL PEDRO MARTINEZ GUTIERREZ 2 | E9: 02006 | F9: ALBACETE | G9: ALBACETE | H9: +34 967190388 | I9: cebriancb@outlook.com | J9: 1004D | K9: 0 | L9: NACREQ | M9: 4 | N9: SUR-900-11 | O9: 22 | P9: ES | Q9: NOEL BLANCO CURSA
A10: 544 | B10: PIQUET ORTEGA, SILVIA | C10: 40992757H | D10: CL VALENCIA 571 | E10: 08026 | F10: BARCELONA | G10: BARCELONA | H10: +34 932462948 | I10: silviapiquet22@hotmail.com | J10: 1004D | K10: 0 | L10: NACREQ | M10: 4 | N10: PRL-900-11 | O10: 26 | P10: ES | Q10: NOEL BLANCO CURSA
A11: 554 | B11: DOMINGUEZ RIVAS, Mª CARMEN | C11: 46637143C | D11: CL MAYOR 27 | E11: 08740 | F11: SANT ANDREU DE LA BARCA | G11: BARCELONA | H11: +34 600601739 | I11: lalunacomercial96@gmail.com | J11: 1004D | K11: 0 | L11: NACREQ | M11: 4 | N11: PRL-900-11 | O11: 26 | P11: ES | Q11: NOEL BLANCO CURSA
A12: 567 | B12: GRUP D'IMATGE JORDI, S.L. | C12: B17466483 | D12: CL PAGES I MORATO 23 | E12: 17200 | F12: PALAFRUGELL | G12: GIRONA | H12: +34 972302662 | I12: grupdimatgejordi@hotmail.com | J12: 1004D | K12: 0 | L12: NACIONAL | M12: 4 | N12: PRL-900-11 | O12: 10 | P12: ES | Q12: NOEL BLANCO CURSA
A13: 705 | B13: COOP. PELUQUEROS PALENTINOS | C13: F34152694 | D13: AV CARDENAL CISNEROS 22 | E13: 34002 | F13: PALENCIA | G13: PALENCIA | H13: +34 979710187 | I13: copepale@gmail.com | J13: 1004D | K13: 0 | L13: NACIONAL | M13: 4 | N13: NOR-900-11 | O13: 10 | P13: ES | Q13: NOEL BLANCO CURSA
... A103: 10697 | B103: GIRONA COSMETICS, SLP | C103: B16391062 | D103: RONDA FERRAN PUIG 23, LOCAL | E103: 17001 | F103: GIRONA | G103: GIRONA | H103: +34 607157640 | I103: GIRONACOSMETICS@GMAIL.COM | J103: 1004D | K103: 0 | L103: NACIONAL | M103: 4 | N103: PRL-900-11 | O103: 10 | P103: ES | Q103: NOEL BLANCO CURSA

Sheet T.P.
A1: CÓDIGO T.P. | B1: DESCRIPCIÓN T.P.
A2: 3 | B2: 30 DÍAS
A3: 4 | B3: 30-60 DÍAS
